Workbook

Sheet Dim Customers
A1: Customer ID | B1: Customer Name | C1: City | D1: State | E1: Pincode | F1: EmailID | G1: Phone Number
A2: 1 | B2: Aarav Singh | C2: Nagpur | D2: Maharashtra | E2: 440001 | F2: 1Aarav@gmail.com | G2: 860135097
A3: 2 | B3: Aditi Patel | C3: Bhopal | D3: Madhya Pradesh | E3: 462001 | F3: 2Aditi@gmail.com | G3: 896750475
A4: 3 | B4: Aman Verma | C4: Ahmedabad | D4: Gujarat | E4: 380001 | F4: 3Aman@gmail.com | G4: 833807373
A5: 4 | B5: Ananya Mehta | C5: Bhopal | D5: Madhya Pradesh | E5: 462001 | F5: 4Ananya@gmail.com | G5: 804038105
A6: 5 | B6: Aniket Sharma | C6: Indore | D6: Madhya Pradesh | E6: 452001 | F6: 5Aniket@gmail.com | G6: 986307349
A7: 6 | B7: Anjali Rao | C7: Bhopal | D7: Madhya Pradesh | E7: 462001 | F7: 6Anjali@gmail.com | G7: 963288063
A8: 7 | B8: Arjun Joshi | C8: Kanpur | D8: Uttar Pradesh | E8: 208001 | F8: 7Arjun@gmail.com | G8: 988368456
A9: 8 | B9: Aryan Gupta | C9: Mumbai | D9: Maharashtra | E9: 400001 | F9: 8Aryan@gmail.com | G9: 953821775
A10: 9 | B10: Avni Iyer | C10: Kanpur | D10: Uttar Pradesh | E10: 208001 | F10: 9Avni@gmail.com | G10: 863732487
A11: 10 | B11: Dhruv Desai | C11: Pune | D11: Maharashtra | E11: 411001 | F11: 10Dhruv@gmail.com | G11: 900051106
A12: 11 | B12: Diya Kapoor | C12: Mumbai | D12: Maharashtra | E12: 400001 | F12: 11Diya@gmail.com | G12: 845767347
A13: 12 | B13: Gaurav Nair | C13: Pune | D13: Maharashtra | E13: 411001 | F13: 12Gaurav@gmail.com | G13: 882241217
... A51: 50 | B51: Yash Malhotra | C51: Lucknow | D51: Uttar Pradesh | E51: 226001 | F51: 50Yash@gmail.com | G51: 910695779

Sheet Dim Product
A1: ProductID | B1: Product Name | C1: Product Line | D1: Price (INR)
A2: P001 | B2: Apple iPhone 14 | C2: Electronics | D2: 79999
A3: P002 | B3: Samsung Galaxy S21 | C3: Electronics | D3: 69999
A4: P003 | B4: Sony Bravia 55" TV | C4: Electronics | D4: 89999
A5: P004 | B5: HP Pavilion Laptop | C5: Electronics | D5: 64999
A6: P005 | B6: Apple MacBook Air | C6: Electronics | D6: 92499
A7: P006 | B7: Nike Running Shoes | C7: Footwear | D7: 7499
A8: P007 | B8: Adidas Sneakers | C8: Footwear | D8: 6999
A9: P008 | B9: Puma Sports Shoes | C9: Footwear | D9: 5499
A10: P009 | B10: Levi's Denim Jeans | C10: Clothing | D10: 3499
A11: P010 | B11: Zara Casual Shirt | C11: Clothing | D11: 2199
A12: P011 | B12: H&M T-Shirt | C12: Clothing | D12: 1499
A13: P012 | B13: FabIndia Kurta | C13: Clothing | D13: 2999
... A31: P030 | B31: Nivea Body Lotion | C31: Personal Care | D31: 399

Sheet Dim Promotion 
A1: PromotionID | B1: Promotion Name | C1: Ad Type | D1: Coupon Code | E1: Price Reduction Type
A2: PR001 | B2: Summer Sale | C2: Email | D2: SUMMER21 | E2: 20
A3: PR002 | B3: Festive Diwali | C3: Social Media | D3: FESTIVE2022 | E3: 10
A4: PR003 | B4: New Year Special | C4: Website Banner | D4: NEWYEAR22 | E4: 50
A5: PR004 | B5: Weekend Flash Sale | C5: Mobile Push | D5: FLASH50 | E5: 50
A6: PR005 | B6: Clearance Sale | C6: In-App | D6: CLEARANCE23 | E6: 70

Sheet Sheet3
A1: Date (dd/mm/yyyy) | B1: CustomerID | C1: (leave empty) | D1: Product ID | E1: Units Sold | F1: Price Per Unit | G1: Total Sales | H1: Discount Percentage | I1: Discount Value | J1: Net Sales
A2: 43865 | B2: 10 | C2: 0 | D2: P004 | E2: 2 | F2: =VLOOKUP(D2,'Dim Product'!A:D,4,FALSE) -> 64999 | G2: =E2*F2 -> 129998 | H2: 0 | I2: =G2*H2/100 -> 0 | J2: =G2-I2 -> 129998 | K2: =TRIM(C2) -> 0
A3: 44700 | B3: 28 | C3: PR003 | D3: P027 | E3: 3 | F3: =VLOOKUP(D3,'Dim Product'!A:D,4,FALSE) -> 699 | G3: =E3*F3 -> 2097 | H3: 0 | I3: =G3*H3/100 -> 0 | J3: =G3-I3 -> 2097 | K3: =TRIM(C3) -> PR003
A4: 44743 | B4: 2 | C4: 0 | D4: P011 | E4: 3 | F4: =VLOOKUP(D4,'Dim Product'!A:D,4,FALSE) -> 1499 | G4: =E4*F4 -> 4497 | H4: 0 | I4: =G4*H4/100 -> 0 | J4: =G4-I4 -> 4497 | K4: =TRIM(C4) -> 0
A5: 44657 | B5: 11 | C5: PR001 | D5: P009 | E5: 2 | F5: =VLOOKUP(D5,'Dim Product'!A:D,4,FALSE) -> 3499 | G5: =E5*F5 -> 6998 | H5: 20 | I5: =G5*H5/100 -> 1399.6 | J5: =G5-I5 -> 5598.4 | K5: =TRIM(C5) -> PR001
A6: 44563 | B6: 34 | C6: 0 | D6: P002 | E6: 1 | F6: =VLOOKUP(D6,'Dim Product'!A:D,4,FALSE) -> 69999 | G6: =E6*F6 -> 69999 | H6: 0 | I6: =G6*H6/100 -> 0 | J6: =G6-I6 -> 69999 | K6: =TRIM(C6) -> 0
A7: 44968 | B7: 44 | C7: 0 | D7: P019 | E7: 1 | F7: =VLOOKUP(D7,'Dim Product'!A:D,4,FALSE) -> 5999 | G7: =E7*F7 -> 5999 | H7: 0 | I7: =G7*H7/100 -> 0 | J7: =G7-I7 -> 5999 | K7: =TRIM(C7) -> 0
A8: 45122 | B8: 42 | C8: PR004 | D8: P014 | E8: 2 | F8: =VLOOKUP(D8,'Dim Product'!A:D,4,FALSE) -> 4999 | G8: =E8*F8 -> 9998 | H8: 50 | I8: =G8*H8/100 -> 4999 | J8: =G8-I8 -> 4999 | K8: =TRIM(C8) -> PR004
A9: 44224 | B9: 46 | C9: 0 | D9: P025 | E9: 1 | F9: =VLOOKUP(D9,'Dim Product'!A:D,4,FALSE) -> 8999 | G9: =E9*F9 -> 8999 | H9: 0 | I9: =G9*H9/100 -> 0 | J9: =G9-I9 -> 8999 | K9: =TRIM(C9) -> 0
A10: 44706 | B10: 21 | C10: PR001 | D10: P019 | E10: 2 | F10: =VLOOKUP(D10,'Dim Product'!A:D,4,FALSE) -> 5999 | G10: =E10*F10 -> 11998 | H10: 20 | I10: =G10*H10/100 -> 2399.6 | J10: =G10-I10 -> 9598.4 | K10: =TRIM(C10) -> PR001
A11: 45071 | B11: 48 | C11: PR001 | D11: P005 | E11: 3 | F11: =VLOOKUP(D11,'Dim Product'!A:D,4,FALSE) -> 92499 | G11: =E11*F11 -> 277497 | H11: 20 | I11: =G11*H11/100 -> 55499.4 | J11: =G11-I11 -> 221997.6 | K11: =TRIM(C11) -> PR001
A12: 45202 | B12: 18 | C12: 0 | D12: P001 | E12: 1 | F12: =VLOOKUP(D12,'Dim Product'!A:D,4,FALSE) -> 79999 | G12: =E12*F12 -> 79999 | H12: 0 | I12: =G12*H12/100 -> 0 | J12: =G12-I12 -> 79999 | K12: =TRIM(C12) -> 0
A13: 44066 | B13: 28 | C13: 0 | D13: P010 | E13: 2 | F13: =VLOOKUP(D13,'Dim Product'!A:D,4,FALSE) -> 2199 | G13: =E13*F13 -> 4398 | H13: 0 | I13: =G13*H13/100 -> 0 | J13: =G13-I13 -> 4398 | K13: =TRIM(C13) -> 0
A14: 45075 | B14: 17 | C14: PR001 | D14: P002 | E14: 3 | F14: =VLOOKUP(D14,'Dim Product'!A:D,4,FALSE) -> 69999 | G14: =E14*F14 -> 209997 | H14: 20 | I14: =G14*H14/100 -> 41999.4 | J14: =G14-I14 -> 167997.6 | K14: =TRIM(C14) -> PR001
A15: 45115 | B15: 28 | C15: PR004 | D15: P002 | E15: 3 | F15: =VLOOKUP(D15,'Dim Product'!A:D,4,FALSE) -> 69999 | G15: =E15*F15 -> 209997 | H15: 50 | I15: =G15*H15/100 -> 104998.5 | J15: =G15-I15 -> 104998.5 | K15: =TRIM(C15) -> PR004
A16: 44908 | B16: 23 | C16: 0 | D16: P002 | E16: 3 | F16: =VLOOKUP(D16,'Dim Product'!A:D,4,FALSE) -> 69999 | G16: =E16*F16 -> 209997 | H16: 0 | I16: =G16*H16/100 -> 0 | J16: =G16-I16 -> 209997 | K16: =TRIM(C16) -> 0
A17: 44147 | B17: 8 | C17: 0 | D17: P029 | E17: 1 | F17: =VLOOKUP(D17,'Dim Product'!A:D,4,FALSE) -> 99 | G17: =E17*F17 -> 99 | H17: 0 | I17: =G17*H17/100 -> 0 | J17: =G17-I17 -> 99 | K17: =TRIM(C17) -> 0
A18: 44910 | B18: 41 | C18: 0 | D18: P022 | E18: 3 | F18: =VLOOKUP(D18,'Dim Product'!A:D,4,FALSE) -> 1999 | G18: =E18*F18 -> 5997 | H18: 0 | I18: =G18*H18/100 -> 0 | J18: =G18-I18 -> 5997 | K18: =TRIM(C18) -> 0
A19: 44562 | B19: 48 | C19: PR003 | D19: P011 | E19: 3 | F19: =VLOOKUP(D19,'Dim Product'!A:D,4,FALSE) -> 1499 | G19: =E19*F19 -> 4497 | H19: 50 | I19: =G19*H19/100 -> 2248.5 | J19: =G19-I19 -> 2248.5 | K19: =TRIM(C19) -> PR003
A20: 44105 | B20: 12 | C20: 0 | D20: P010 | E20: 1 | F20: =VLOOKUP(D20,'Dim Product'!A:D,4,FALSE) -> 2199 | G20: =E20*F20 -> 2199 | H20: 0 | I20: =G20*H20/100 -> 0 | J20: =G20-I20 -> 2199 | K20: =TRIM(C20) -> 0
A21: 44508 | B21: 40 | C21: 0 | D21: P012 | E21: 1 | F21: =VLOOKUP(D21,'Dim Product'!A:D,4,FALSE) -> 2999 | G21: =E21*F21 -> 2999 | H21: 0 | I21: =G21*H21/100 -> 0 | J21: =G21-I21 -> 2999 | K21: =TRIM(C21) -> 0
A22: 44001 | B22: 31 | C22: 0 | D22: P016 | E22: 3 | F22: =VLOOKUP(D22,'Dim Product'!A:D,4,FALSE) -> 24999 | G22: =E22*F22 -> 74997 | H22: 0 | I22: =G22*H22/100 -> 0 | J22: =G22-I22 -> 74997 | K22: =TRIM(C22) -> 0
A23: 44399 | B23: 6 | C23: 0 | D23: P023 | E23: 3 | F23: =VLOOKUP(D23,'Dim Product'!A:D,4,FALSE) -> 1499 | G23: =E23*F23 -> 4497 | H23: 0 | I23: =G23*H23/100 -> 0 | J23: =G23-I23 -> 4497 | K23: =TRIM(C23) -> 0
A24: 44959 | B24: 25 | C24: 0 | D24: P029 | E24: 2 | F24: =VLOOKUP(D24,'Dim Product'!A:D,4,FALSE) -> 99 | G24: =E24*F24 -> 198 | H24: 0 | I24: =G24*H24/100 -> 0 | J24: =G24-I24 -> 198 | K24: =TRIM(C24) -> 0
A25: 44599 | B25: 27 | C25: 0 | D25: P028 | E25: 2 | F25: =VLOOKUP(D25,'Dim Product'!A:D,4,FALSE) -> 349 | G25: =E25*F25 -> 698 | H25: 0 | I25: =G25*H25/100 -> 0 | J25: =G25-I25 -> 698 | K25: =TRIM(C25) -> 0
A26: 43919 | B26: 31 | C26: 0 | D26: P008 | E26: 2 | F26: =VLOOKUP(D26,'Dim Product'!A:D,4,FALSE) -> 5499 | G26: =E26*F26 -> 10998 | H26: 0 | I26: =G26*H26/100 -> 0 | J26: =G26-I26 -> 10998 | K26: =TRIM(C26) -> 0
A27: 44247 | B27: 40 | C27: 0 | D27: P013 | E27: 1 | F27: =VLOOKUP(D27,'Dim Product'!A:D,4,FALSE) -> 15999 | G27: =E27*F27 -> 15999 | H27: 0 | I27: =G27*H27/100 -> 0 | J27: =G27-I27 -> 15999 | K27: =TRIM(C27) -> 0
A28: 43947 | B28: 3 | C28: PR001 | D28: P005 | E28: 3 | F28: =VLOOKUP(D28,'Dim Product'!A:D,4,FALSE) -> 92499 | G28: =E28*F28 -> 277497 | H28: 20 | I28: =G28*H28/100 -> 55499.4 | J28: =G28-I28 -> 221997.6 | K28: =TRIM(C28) -> PR001
A29: 44931 | B29: 44 | C29: 0 | D29: P016 | E29: 2 | F29: =VLOOKUP(D29,'Dim Product'!A:D,4,FALSE) -> 24999 | G29: =E29*F29 -> 49998 | H29: 0 | I29: =G29*H29/100 -> 0 | J29: =G29-I29 -> 49998 | K29: =TRIM(C29) -> 0
A30: 44630 | B30: 2 | C30: 0 | D30: P010 | E30: 3 | F30: =VLOOKUP(D30,'Dim Product'!A:D,4,FALSE) -> 2199 | G30: =E30*F30 -> 6597 | H30: 0 | I30: =G30*H30/100 -> 0 | J30: =G30-I30 -> 6597 | K30: =TRIM(C30) -> 0
A31: 44304 | B31: 17 | C31: PR001 | D31: P017 | E31: 1 | F31: =VLOOKUP(D31,'Dim Product'!A:D,4,FALSE) -> 10499 | G31: =E31*F31 -> 10499 | H31: 20 | I31: =G31*H31/100 -> 2099.8 | J31: =G31-I31 -> 8399.2 | K31: =TRIM(C31) -> PR001
A32: 43860 | B32: 1 | C32: 0 | D32: P018 | E32: 1 | F32: =VLOOKUP(D32,'Dim Product'!A:D,4,FALSE) -> 2299 | G32: =E32*F32 -> 2299 | H32: 0 | I32: =G32*H32/100 -> 0 | J32: =G32-I32 -> 2299 | K32: =TRIM(C32) -> 0
A33: 44332 | B33: 43 | C33: PR001 | D33: P001 | E33: 3 | F33: =VLOOKUP(D33,'Dim Product'!A:D,4,FALSE) -> 79999 | G33: =E33*F33 -> 239997 | H33: 20 | I33: =G33*H33/100 -> 47999.4 | J33: =G33-I33 -> 191997.6 | K33: =TRIM(C33) -> PR001
A34: 43881 | B34: 24 | C34: 0 | D34: P020 | E34: 2 | F34: =VLOOKUP(D34,'Dim Product'!A:D,4,FALSE) -> 12999 | G34: =E34*F34 -> 25998 | H34: 0 | I34: =G34*H34/100 -> 0 | J34: =G34-I34 -> 25998 | K34: =TRIM(C34) -> 0
A35: 44071 | B35: 14 | C35: 0 | D35: P017 | E35: 3 | F35: =VLOOKUP(D35,'Dim Product'!A:D,4,FALSE) -> 10499 | G35: =E35*F35 -> 31497 | H35: 0 | I35: =G35*H35/100 -> 0 | J35: =G35-I35 -> 31497 | K35: =TRIM(C35) -> 0
A36: 44616 | B36: 20 | C36: 0 | D36: P013 | E36: 3 | F36: =VLOOKUP(D36,'Dim Product'!A:D,4,FALSE) -> 15999 | G36: =E36*F36 -> 47997 | H36: 0 | I36: =G36*H36/100 -> 0 | J36: =G36-I36 -> 47997 | K36: =TRIM(C36) -> 0
A37: 44092 | B37: 14 | C37: 0 | D37: P025 | E37: 2 | F37: =VLOOKUP(D37,'Dim Product'!A:D,4,FALSE) -> 8999 | G37: =E37*F37 -> 17998 | H37: 0 | I37: =G37*H37/100 -> 0 | J37: =G37-I37 -> 17998 | K37: =TRIM(C37) -> 0
A38: 44016 | B38: 49 | C38: PR004 | D38: P023 | E38: 1 | F38: =VLOOKUP(D38,'Dim Product'!A:D,4,FALSE) -> 1499 | G38: =E38*F38 -> 1499 | H38: 50 | I38: =G38*H38/100 -> 749.5 | J38: =G38-I38 -> 749.5 | K38: =TRIM(C38) -> PR004
A39: 44357 | B39: 31 | C39: 0 | D39: P014 | E39: 1 | F39: =VLOOKUP(D39,'Dim Product'!A:D,4,FALSE) -> 4999 | G39: =E39*F39 -> 4999 | H39: 0 | I39: =G39*H39/100 -> 0 | J39: =G39-I39 -> 4999 | K39: =TRIM(C39) -> 0
A40: 45291 | B40: 29 | C40: PR005 | D40: P018 | E40: 1 | F40: =VLOOKUP(D40,'Dim Product'!A:D,4,FALSE) -> 2299 | G40: =E40*F40 -> 2299 | H40: 70 | I40: =G40*H40/100 -> 1609.3 | J40: =G40-I40 -> 689.7 | K40: =TRIM(C40) -> PR005
...
